Exception ignored in: <function _ProactorBasePipeTransport.__del__ at 0x000001F2DE9A8820>
Traceback (most recent call last):
  File "C:\Program Files\Python310\lib\asyncio\proactor_events.py", line 116, in __del__
    self.close()
  File "C:\Program Files\Python310\lib\asyncio\proactor_events.py", line 108, in close
    self._loop.call_soon(self._call_connection_lost, None)
  File "C:\Program Files\Python310\lib\asyncio\base_events.py", line 745, in call_soon
    self._check_closed()
  File "C:\Program Files\Python310\lib\asyncio\base_events.py", line 510, in _check_closed
    raise RuntimeError('Event loop is closed')
RuntimeError: Event loop is closed
